<mujoco model="ur5e_mocap">
    <!-- 옵션 설정 -->
    <option timestep="0.002" gravity="0 0 -9.81" iterations="50" integrator="RK4" />
    
    <!-- 자산(asset) 섹션 -->
    <asset>
        <!-- 재질 정의 -->
        <material name="Black" specular="0.5" shininess="0.25" rgba="0.033102 0.033102 0.033102 1.000000"/>
        <material name="JointGrey" specular="0.5" shininess="0.25" rgba="0.278431 0.278431 0.278431 1.000000"/>
        <material name="LinkGrey" specular="0.5" shininess="0.25" rgba="0.820392 0.820392 0.820392 1.000000"/>
        <material name="URBlue" specular="0.5" shininess="0.25" rgba="0.490196 0.678431 0.800000 1.000000"/>
        
        <!-- 메쉬 정의 -->
        <!-- base material and mesh -->
        <mesh name="base_vis_0" file="obj_meshes/base_vis/base_vis_0.obj"/>
        <mesh name="base_vis_1" file="obj_meshes/base_vis/base_vis_1.obj"/>

        <!-- forearm mesh -->	
        <mesh name="forearm_vis_0" file="obj_meshes/forearm_vis/forearm_vis_0.obj"/>
        <mesh name="forearm_vis_1" file="obj_meshes/forearm_vis/forearm_vis_1.obj"/>
        <mesh name="forearm_vis_2" file="obj_meshes/forearm_vis/forearm_vis_2.obj"/>
        <mesh name="forearm_vis_3" file="obj_meshes/forearm_vis/forearm_vis_3.obj"/>

        <!-- shoulder material and mesh -->	
        <mesh name="shoulder_vis_0" file="obj_meshes/shoulder_vis/shoulder_vis_0.obj"/>
        <mesh name="shoulder_vis_1" file="obj_meshes/shoulder_vis/shoulder_vis_1.obj"/>
        <mesh name="shoulder_vis_2" file="obj_meshes/shoulder_vis/shoulder_vis_2.obj"/>

        <!-- upperarm material and mesh -->
        <mesh name="upperarm_vis_0" file="obj_meshes/upperarm_vis/upperarm_vis_0.obj"/>
        <mesh name="upperarm_vis_1" file="obj_meshes/upperarm_vis/upperarm_vis_1.obj"/>
        <mesh name="upperarm_vis_2" file="obj_meshes/upperarm_vis/upperarm_vis_2.obj"/>
        <mesh name="upperarm_vis_3" file="obj_meshes/upperarm_vis/upperarm_vis_3.obj"/>

        <!-- wrist1 material and mesh -->	
        <mesh name="wrist1_vis_0" file="obj_meshes/wrist1_vis/wrist1_vis_0.obj"/>
        <mesh name="wrist1_vis_1" file="obj_meshes/wrist1_vis/wrist1_vis_1.obj"/>
        <mesh name="wrist1_vis_2" file="obj_meshes/wrist1_vis/wrist1_vis_2.obj"/>

        <!-- wrist2 material and mesh -->	
        <mesh name="wrist2_vis_0" file="obj_meshes/wrist2_vis/wrist2_vis_0.obj"/>
        <mesh name="wrist2_vis_1" file="obj_meshes/wrist2_vis/wrist2_vis_1.obj"/>
        <mesh name="wrist2_vis_2" file="obj_meshes/wrist2_vis/wrist2_vis_2.obj"/>

        <!-- wrist3 material and mesh -->	
        <mesh name="wrist3_vis" file="obj_meshes/wrist3_vis/wrist3_vis.obj"/>
        
        <!-- 충돌 메쉬 -->
        <mesh name="base" file="meshes/base.stl" />
        <mesh name="shoulder" file="meshes/shoulder.stl" />
        <mesh name="upperarm" file="meshes/upperarm.stl" />
        <mesh name="forearm" file="meshes/forearm.stl" />
        <mesh name="wrist1" file="meshes/wrist1.stl" />
        <mesh name="wrist2" file="meshes/wrist2.stl" />
        <mesh name="wrist3" file="meshes/wrist3.stl" />
    </asset>

    <!-- 등가 제약조건(equality constraints) 수정 -->
    <equality>
        <!-- 말단 이펙터를 모캡 본체에 용접하여 위치와 자세를 고정 -->
        <weld body1="right_hand" body2="mocap_body" />
    </equality>

    <!-- 월드 본체 -->
    <worldbody>
        <!-- 루트 바디: base -->
        <body name="base" pos="0 0 0">
            <!-- 로봇 뷰 카메라 -->
            <camera mode="fixed" name="robotview" pos="1.0 0 0.4" quat="0.653 0.271 0.271 0.653"/>
            <inertial diaginertia="0 0 0" mass="0" pos="0 0 0"/>
            <!-- 베이스 시각적 요소 -->
            <geom mesh="base_vis_0" material="Black" type="mesh" contype="0" conaffinity="0" group="1"/>
            <geom mesh="base_vis_1" material="JointGrey" type="mesh" contype="0" conaffinity="0" group="1"/>

            <!-- 베이스 충돌 메쉬 -->
            <geom type="mesh" rgba="0.7 0.7 0.7 1" mesh="base" name="base_col"/>

            <!-- 어깨 링크 -->
            <body name="shoulder_link" pos="0 0 0.163">
                <inertial pos="0 0 0" mass="3.7" diaginertia="0.0102675 0.0102675 0.00666" />
                <joint name="shoulder_pan_joint" pos="0 0 0" axis="0 0 1" limited="true" range="-6.28319 6.28319" damping="0.001" frictionloss="0.01" />
                <!-- 어깨 시각적 요소 -->
                <geom mesh="shoulder_vis_0" material="URBlue" type="mesh" contype="0" conaffinity="0" group="1"/>
                <geom mesh="shoulder_vis_1" material="Black" type="mesh" contype="0" conaffinity="0" group="1"/>
                <geom mesh="shoulder_vis_2" material="JointGrey" type="mesh" contype="0" conaffinity="0" group="1"/>

                <!-- 어깨 충돌 메쉬 -->
                <geom type="mesh" rgba="0.7 0.7 0.7 1" mesh="shoulder" name="shoulder_col" />

                <!-- 상박 링크 -->
                <body name="upper_arm_link" pos="0 0.138 0" quat="0.707107 0 0.707107 0">
                    <inertial pos="0 0 0.2125" mass="8.393" diaginertia="0.133886 0.133886 0.0151074" />
                    <joint name="shoulder_lift_joint" pos="0 0 0" axis="0 1 0" limited="true" range="-6.28319 6.28319" damping="0.001" frictionloss="0.01" />
                    <!-- 상박 시각적 요소 -->
                    <geom mesh="upperarm_vis_0" material="LinkGrey" type="mesh" contype="0" conaffinity="0" group="1"/>
                    <geom mesh="upperarm_vis_1" material="Black" type="mesh" contype="0" conaffinity="0" group="1"/>
                    <geom mesh="upperarm_vis_2" material="JointGrey" type="mesh" contype="0" conaffinity="0" group="1"/>
                    <geom mesh="upperarm_vis_3" material="URBlue" type="mesh" contype="0" conaffinity="0" group="1"/>

                    <!-- 상박 충돌 메쉬 -->
                    <geom type="mesh" rgba="0.7 0.7 0.7 1" mesh="upperarm" name="upperarm_col"/>

                    <!-- 전완 링크 -->
                    <body name="forearm_link" pos="0 -0.131 0.425">
                        <inertial pos="0 0 0.196" mass="2.275" diaginertia="0.0311796 0.0311796 0.004095" />
                        <joint name="elbow_joint" pos="0 0 0" axis="0 1 0" limited="true" range="-3.14159 3.14159" damping="0.001" frictionloss="0.01" />
                        <!-- 전완 시각적 요소 -->
                        <geom mesh="forearm_vis_0" material="URBlue" type="mesh" contype="0" conaffinity="0" group="1"/>
                        <geom mesh="forearm_vis_1" material="LinkGrey" type="mesh" contype="0" conaffinity="0" group="1"/>
                        <geom mesh="forearm_vis_2" material="Black" type="mesh" contype="0" conaffinity="0" group="1"/>
                        <geom mesh="forearm_vis_3" material="JointGrey" type="mesh" contype="0" conaffinity="0" group="1"/>

                        <!-- 전완 충돌 메쉬 -->
                        <geom type="mesh" rgba="0.7 0.7 0.7 1" mesh="forearm" name="forearm_col"/>

                        <!-- 손목1 링크 -->
                        <body name="wrist_1_link" pos="0 0 0.392" quat="0.707107 0 0.707107 0">
                            <inertial pos="0 0.127 0" mass="1.219" diaginertia="0.0025599 0.0025599 0.0021942" />
                            <joint name="wrist_1_joint" pos="0 0 0" axis="0 1 0" limited="true" range="-6.28319 6.28319" damping="0.001" frictionloss="0.01" />
                            <!-- 손목1 시각적 요소 -->
                            <geom mesh="wrist1_vis_0" material="Black" type="mesh" contype="0" conaffinity="0" group="1"/>
                            <geom mesh="wrist1_vis_1" material="URBlue" type="mesh" contype="0" conaffinity="0" group="1"/>
                            <geom mesh="wrist1_vis_2" material="JointGrey" type="mesh" contype="0" conaffinity="0" group="1"/>

                            <!-- 손목1 충돌 메쉬 -->
                            <geom type="mesh" rgba="0.7 0.7 0.7 1" mesh="wrist1" name="wrist1_col" />

                            <!-- 손목2 링크 -->
                            <body name="wrist_2_link" pos="0 0.127 0">
                                <inertial pos="0 0 0.1" mass="1.219" diaginertia="0.0025599 0.0025599 0.0021942" />
                                <joint name="wrist_2_joint" pos="0 0 0" axis="0 0 1" limited="true" range="-6.28319 6.28319" damping="0.001" frictionloss="0.01" />
                                <!-- 손목2 시각적 요소 -->
                                <geom mesh="wrist2_vis_0" material="Black" type="mesh" contype="0" conaffinity="0" group="1"/>
                                <geom mesh="wrist2_vis_1" material="URBlue" type="mesh" contype="0" conaffinity="0" group="1"/>
                                <geom mesh="wrist2_vis_2" material="JointGrey" type="mesh" contype="0" conaffinity="0" group="1"/>

                                <!-- 손목2 충돌 메쉬 -->
                                <geom type="mesh" rgba="0.7 0.7 0.7 1" mesh="wrist2" name="wrist2_col" />

                                <!-- 손목3 링크 -->
                                <body name="wrist_3_link" pos="0 0 0.1">
                                    <inertial pos="0 0.0771683 0" quat="0.707107 0 0 0.707107" mass="0.1889" diaginertia="0.000132134 9.90863e-05 9.90863e-05" />
                                    <joint name="wrist_3_joint" pos="0 0 0" axis="0 1 0" limited="true" range="-6.28319 6.28319" damping="0.001" frictionloss="0.01" />
                                    <!-- 손목3 시각적 요소 -->
                                    <geom material="LinkGrey" mesh="wrist3_vis" type="mesh" contype="0" conaffinity="0" group="1"/>

                                    <!-- 손목3 충돌 메쉬 -->
                                    <geom type="mesh" rgba="0.7 0.7 0.7 1" mesh="wrist3" name="wrist3_col" />
                                    <geom size="0.005 0.005 0.005" pos="0 0.09 0" quat="0.707107 0 0 0.707107" type="box" name="wrist3_col2"/>

                                    <!-- 말단 이펙터 (그리퍼) -->
                                    <body name="right_hand" pos="0 0.098 0" quat="0.707 -0.707 0 0" >
                                        <!-- 그리퍼에 부착된 카메라 -->
                                        <camera mode="fixed" name="eye_in_hand" pos="0.05 0 0" quat="0 0.707108 0.707108 0" fovy="75"/>
                                        <!-- 그리퍼 추가 가능 -->
                                    </body>
                                </body>
                            </body>
                        </body>
                    </body>
                </body>
            </body>

            <!-- 모캡 본체를 base 바디 아래로 이동 -->
            <body name="mocap_body" mocap="true" pos="0.5 0 0.5">
                <geom type="sphere" size="0.02" rgba="1 0 0 0.5" />
            </body>
        </body>
    </worldbody>

    <!-- 기존의 액추에이터 섹션은 제거 또는 주석 처리 -->
    <!--
    <actuator>
        <motor ctrllimited="true" ctrlrange="-150.0 150.0" joint="shoulder_pan_joint" name="torq_j1"/>
        <motor ctrllimited="true" ctrlrange="-150.0 150.0" joint="shoulder_lift_joint" name="torq_j2"/>
        <motor ctrllimited="true" ctrlrange="-150.0 150.0" joint="elbow_joint" name="torq_j3"/>
        <motor ctrllimited="true" ctrlrange="-28.0 28.0" joint="wrist_1_joint" name="torq_j4"/>
        <motor ctrllimited="true" ctrlrange="-28.0 28.0" joint="wrist_2_joint" name="torq_j5"/>
        <motor ctrllimited="true" ctrlrange="-28.0 28.0" joint="wrist_3_joint" name="torq_j6"/>
    </actuator>
    -->
</mujoco>
